<?xml version="1.0" ?>
<!-- =================================================================================== -->
<!-- |    This document was autogenerated by xacro from mira.xacro                     | -->
<!-- |    EDITING THIS FILE BY HAND IS NOT RECOMMENDED                                 | -->
<!-- =================================================================================== -->
<robot name="mira" xmlns:controller="http://playerstage.sourceforge.net/gazebo/xmlschema/#controller" xmlns:interface="http://playerstage.sourceforge.net/gazebo/xmlschema/#interface" xmlns:sensor="http://playerstage.sourceforge.net/gazebo/xmlschema/#sensor">
  <link name="mobile_base_base_link"/>
  <joint name="mobile_base_base_link_to_base" type="fixed">
    <parent link="mobile_base_base_link"/>
    <child link="mobile_base_chassis"/>
    <origin rpy="1.5707963267948966 0 0" xyz="0 0 0"/>
  </joint>
  <link name="mobile_base_chassis">
    <visual>
      <origin rpy="0 -0 0" xyz="0 0 0"/>
      <geometry>
        <mesh filename="package://sps/urdf/mobile_base_models/chassis.stl"/>
      </geometry>
      <material name="chassis_material">
        <color rgba="0.74902 0.74902 0.74902 1.0"/>
      </material>
    </visual>
    <collision>
      <geometry>
        <mesh filename="package://sps/urdf/mobile_base_models/chassis.stl"/>
      </geometry>
    </collision>
    <inertial>
      <origin rpy="0 0 0" xyz="3.03885e-10 0.0866061 -4.21983e-12"/>
      <mass value="22"/>
      <inertia ixx="0.254" ixy="-1.648e-9" ixz="-2.434e-08" iyy="0.656" iyz="3.684e-10" izz="0.532"/>
    </inertial>
  </link>
  <gazebo reference="mobile_base_chassis">
    <material>Gazebo/DarkGrey</material>
  </gazebo>
  <joint name="mobile_base_joint_front_dx" type="continuous">
    <origin rpy="0 0 0" xyz="0.183 0.06 0.1355"/>
    <parent link="mobile_base_chassis"/>
    <child link="mobile_base_omniwheel_front_dx"/>
    <axis xyz="0 0 1"/>
    <limit effort="1" velocity="20"/>
    <joint_properties friction="0.0"/>
  </joint>
  <link name="mobile_base_omniwheel_front_dx">
    <visual>
      <origin rpy="3.141592653589793 0 0" xyz="0 0 0"/>
      <geometry>
        <mesh filename="package://sps/urdf/mobile_base_models/omniwheel_A.stl"/>
      </geometry>
    </visual>
    <collision>
      <origin rpy="3.141592653589793 0 0" xyz="0 0 0"/>
      <geometry>
        <cylinder length="0.08" radius="0.076"/>
      </geometry>
    </collision>
    <inertial>
      <origin rpy="0 1.5707963267948966 0" xyz="0 0 0"/>
      <mass value="3.5"/>
      <inertia ixx="0.006920666666666667" ixy="0" ixz="0" iyx="0" iyy="0.006920666666666667" iyz="0" izx="0" izy="0" izz="0.010108"/>
    </inertial>
  </link>
  <gazebo reference="mobile_base_omniwheel_front_dx">
    <material>Gazebo/Orange</material>
  </gazebo>
  <joint name="mobile_base_joint_front_sx" type="continuous">
    <origin rpy="0 0 0" xyz="0.183 0.06 -0.1355"/>
    <parent link="mobile_base_chassis"/>
    <child link="mobile_base_omniwheel_front_sx"/>
    <axis xyz="0 0 1"/>
    <limit effort="1" velocity="20"/>
    <joint_properties friction="0.0"/>
  </joint>
  <link name="mobile_base_omniwheel_front_sx">
    <visual>
      <origin rpy="3.141592653589793 0 0" xyz="0 0 0"/>
      <geometry>
        <mesh filename="package://sps/urdf/mobile_base_models/omniwheel_B.stl"/>
      </geometry>
    </visual>
    <collision>
      <origin rpy="3.141592653589793 0 0" xyz="0 0 0"/>
      <geometry>
        <cylinder length="0.08" radius="0.076"/>
      </geometry>
    </collision>
    <inertial>
      <origin rpy="0 1.5707963267948966 0" xyz="0 0 0"/>
      <mass value="3.5"/>
      <inertia ixx="0.006920666666666667" ixy="0" ixz="0" iyx="0" iyy="0.006920666666666667" iyz="0" izx="0" izy="0" izz="0.010108"/>
    </inertial>
  </link>
  <gazebo reference="mobile_base_omniwheel_front_sx">
    <material>Gazebo/Orange</material>
  </gazebo>
  <joint name="mobile_base_joint_rear_sx" type="continuous">
    <origin rpy="0 0 0" xyz="-0.183 0.06 -0.1355"/>
    <parent link="mobile_base_chassis"/>
    <child link="mobile_base_omniwheel_rear_sx"/>
    <axis xyz="0 0 1"/>
    <limit effort="1" velocity="20"/>
    <joint_properties friction="0.0"/>
  </joint>
  <link name="mobile_base_omniwheel_rear_sx">
    <visual>
      <origin rpy="3.141592653589793 0 0" xyz="0 0 0"/>
      <geometry>
        <mesh filename="package://sps/urdf/mobile_base_models/omniwheel_A.stl"/>
      </geometry>
    </visual>
    <collision>
      <origin rpy="3.141592653589793 0 0" xyz="0 0 0"/>
      <geometry>
        <cylinder length="0.08" radius="0.076"/>
      </geometry>
    </collision>
    <inertial>
      <origin rpy="0 1.5707963267948966 0" xyz="0 0 0"/>
      <mass value="3.5"/>
      <inertia ixx="0.006920666666666667" ixy="0" ixz="0" iyx="0" iyy="0.006920666666666667" iyz="0" izx="0" izy="0" izz="0.010108"/>
    </inertial>
  </link>
  <gazebo reference="mobile_base_omniwheel_rear_sx">
    <material>Gazebo/Orange</material>
  </gazebo>
  <joint name="mobile_base_joint_rear_dx" type="continuous">
    <origin rpy="0 0 0" xyz="-0.183 0.06 0.1355"/>
    <parent link="mobile_base_chassis"/>
    <child link="mobile_base_omniwheel_rear_dx"/>
    <axis xyz="0 0 1"/>
    <limit effort="1" velocity="20"/>
    <joint_properties friction="0.0"/>
  </joint>
  <link name="mobile_base_omniwheel_rear_dx">
    <visual>
      <origin rpy="3.141592653589793 0 0" xyz="0 0 0"/>
      <geometry>
        <mesh filename="package://sps/urdf/mobile_base_models/omniwheel_B.stl"/>
      </geometry>
    </visual>
    <collision>
      <origin rpy="3.141592653589793 0 0" xyz="0 0 0"/>
      <geometry>
        <cylinder length="0.08" radius="0.076"/>
      </geometry>
    </collision>
    <inertial>
      <origin rpy="0 1.5707963267948966 0" xyz="0 0 0"/>
      <mass value="3.5"/>
      <inertia ixx="0.006920666666666667" ixy="0" ixz="0" iyx="0" iyy="0.006920666666666667" iyz="0" izx="0" izy="0" izz="0.010108"/>
    </inertial>
  </link>
  <gazebo reference="mobile_base_omniwheel_rear_dx">
    <material>Gazebo/Orange</material>
  </gazebo>
  <joint name="mobile_base_camera_joint" type="fixed">
    <origin rpy="1.5707963267948966 0 1.5707963267948966" xyz="0.285 0 0.075"/>
    <parent link="mobile_base_base_link"/>
    <child link="mobile_base_camera_rgb_frame"/>
  </joint>
  <link name="mobile_base_camera_rgb_frame">
    <visual name="visual">
      <pose>0 0 0.27 0 0 0</pose>
      <geometry>
        <mesh filename="package://realsense2_description/meshes/d435.dae"/>
      </geometry>
    </visual>
    <collision>
      <origin rpy="0 0 0" xyz="0 0 0"/>
      <geometry>
        <cylinder length="0.062" radius="0.03"/>
      </geometry>
    </collision>
  </link>
  <gazebo reference="mobile_base_camera_rgb_frame">
    <material>Gazebo/Orange</material>
  </gazebo>
  <!--
	<joint name="${prefix}_lidar_joint" type="fixed">
	  <origin xyz = "0.285 0 0.12" rpy = "${PI/2} 0 ${PI/2}"/>
	  <parent link="${prefix}_base_link"/>
          <child link="${prefix}_lidar_frame"/>
	</joint>
	
	<link name="${prefix}_lidar_frame">
		<visual name="visual">
                 <pose>0 0 0.27 0 0 0</pose>
                 <geometry>
                   <cylinder length="0.062" radius="0.03" />
                 </geometry>
               </visual>
		
		<collision>
			<origin xyz="0 0 0" rpy="0 0 0"/>
			<geometry>
				<cylinder length="0.062" radius="0.03" />
			</geometry>
		</collision>
	</link>
	<gazebo reference="${prefix}_lidar_frame">
		<material>Gazebo/Orange</material>
	</gazebo>
	
	<joint name="${prefix}_2d_lidar_joint" type="fixed">
	  <origin xyz = "0.18 0 0.17" rpy = "${PI/2} 0 ${PI/2}"/>
	  <parent link="${prefix}_base_link"/>
          <child link="${prefix}_2d_lidar_frame"/>
	</joint>
	
	<link name="${prefix}_2d_lidar_frame">
		<visual name="visual">
                 <pose>0 0 0.27 0 0 0</pose>
                 <geometry>
                   <cylinder length="0.062" radius="0.03" />
                 </geometry>
               </visual>
		
		<collision>
			<origin xyz="0 0 0" rpy="0 0 0"/>
			<geometry>
				<cylinder length="0.062" radius="0.03" />
			</geometry>
		</collision>
	</link>
	<gazebo reference="${prefix}_2d_lidar_frame">
		<material>Gazebo/Orange</material>
	</gazebo>
	-->
  <gazebo>
    <plugin filename="libgazebo_ros_planar_move.so" name="robot_controller">
      <commandTopic>cmd_vel</commandTopic>
      <odometryTopic>odom</odometryTopic>
      <odometryFrame>odom</odometryFrame>
      <odometryRate>20.0</odometryRate>
      <robotBaseFrame>base_link</robotBaseFrame>
    </plugin>
  </gazebo>
  <gazebo reference="mobile_base_camera_rgb_frame">
    <sensor name="camera" type="camera">
      <update_rate>30.0</update_rate>
      <camera name="head">
        <horizontal_fov>1.97222</horizontal_fov>
        <image>
          <width>1920</width>
          <height>1080</height>
          <format>R8G8B8</format>
        </image>
        <clip>
          <near>0.02</near>
          <far>100</far>
        </clip>
        <noise>
          <type>gaussian</type>
          <mean>0.0</mean>
          <stddev>0.007</stddev>
        </noise>
      </camera>
      <plugin filename="libgazebo_ros_camera.so" name="camera_controller">
        <alwaysOn>true</alwaysOn>
        <updateRate>0.0</updateRate>
        <cameraName>mobile_base_camera</cameraName>
        <imageTopicName>mobile_base_image_raw</imageTopicName>
        <cameraInfoTopicName>mobile_base_camera_info</cameraInfoTopicName>
        <frameName>mobile_base_camera_rgb_optical_frame</frameName>
        <hackBaseline>0.07</hackBaseline>
        <distortionK1>-0.35925741</distortionK1>
        <distortionK2>0.16575977</distortionK2>
        <distortionK3>-0.03662964</distortionK3>
        <distortionT1>0.00264587</distortionT1>
        <distortionT2>0.00037099</distortionT2>
      </plugin>
    </sensor>
  </gazebo>
  <!-- Bumpers -->
  <gazebo reference="mobile_base_chassis">
    <sensor name="mobile_base_chassis_bumper" type="contact">
      <alwaysOn>true</alwaysOn>
      <updateRate>30.0</updateRate>
      <contact>
        <collision>base_link_fixed_joint_lump__mobile_base_chassis_collision</collision>
      </contact>
      <plugin filename="libgazebo_ros_bumper.so" name="gazebo_ros_bumper_controller">
        <bumperTopicName>bumper</bumperTopicName>
        <frameName>world</frameName>
        <updateRate>30.0</updateRate>
      </plugin>
    </sensor>
  </gazebo>
  <gazebo reference="mobile_base_omniwheel_front_dx">
    <sensor name="mobile_base_omniwheel_front_dx_collision_bumper" type="contact">
      <alwaysOn>true</alwaysOn>
      <updateRate>30.0</updateRate>
      <contact>
        <collision>mobile_base_omniwheel_front_dx_collision</collision>
      </contact>
      <plugin filename="libgazebo_ros_bumper.so" name="gazebo_ros_bumper_controller">
        <bumperTopicName>bumper</bumperTopicName>
        <frameName>world</frameName>
        <updateRate>30.0</updateRate>
      </plugin>
    </sensor>
  </gazebo>
  <gazebo reference="mobile_base_omniwheel_front_sx">
    <sensor name="mobile_base_omniwheel_front_sx_collision_bumper" type="contact">
      <alwaysOn>true</alwaysOn>
      <updateRate>30.0</updateRate>
      <contact>
        <collision>mobile_base_omniwheel_front_sx_collision</collision>
      </contact>
      <plugin filename="libgazebo_ros_bumper.so" name="gazebo_ros_bumper_controller">
        <bumperTopicName>bumper</bumperTopicName>
        <frameName>world</frameName>
        <updateRate>30.0</updateRate>
      </plugin>
    </sensor>
  </gazebo>
  <gazebo reference="mobile_base_omniwheel_rear_dx">
    <sensor name="mobile_base_omniwheel_rear_dx_collision_bumper" type="contact">
      <alwaysOn>true</alwaysOn>
      <updateRate>30.0</updateRate>
      <contact>
        <collision>mobile_base_omniwheel_rear_dx_collision</collision>
      </contact>
      <plugin filename="libgazebo_ros_bumper.so" name="gazebo_ros_bumper_controller">
        <bumperTopicName>bumper</bumperTopicName>
        <frameName>world</frameName>
        <updateRate>30.0</updateRate>
      </plugin>
    </sensor>
  </gazebo>
  <gazebo reference="mobile_base_omniwheel_rear_sx">
    <sensor name="mobile_base_omniwheel_rear_sx_collision_bumper" type="contact">
      <alwaysOn>true</alwaysOn>
      <updateRate>30.0</updateRate>
      <contact>
        <collision>mobile_base_omniwheel_rear_sx_collision</collision>
      </contact>
      <plugin filename="libgazebo_ros_bumper.so" name="gazebo_ros_bumper_controller">
        <bumperTopicName>bumper</bumperTopicName>
        <frameName>world</frameName>
        <updateRate>30.0</updateRate>
      </plugin>
    </sensor>
  </gazebo>
  <gazebo>
    <plugin filename="libgazebo_ros_p3d.so" name="p3d_base_controller">
      <alwaysOn>true</alwaysOn>
      <updateRate>50.0</updateRate>
      <bodyName>base_link</bodyName>
      <topicName>ground_truth/odom</topicName>
      <gaussianNoise>0.01</gaussianNoise>
      <frameName>world</frameName>
      <xyzOffsets>0 0 0</xyzOffsets>
      <rpyOffsets>0 0 0</rpyOffsets>
    </plugin>
  </gazebo>
  <joint name="base_laser_front_hokuyo_urg04_laser_joint" type="fixed">
    <axis xyz="0 1 0"/>
    <origin rpy="0 0 0" xyz="0.2 0 0.21"/>
    <parent link="base_link"/>
    <child link="base_laser_front_link"/>
  </joint>
  <link name="base_laser_front_link">
    <inertial>
      <mass value="0.16"/>
      <origin rpy="0 0 0" xyz="0 0 0"/>
      <inertia ixx="0.1" ixy="0" ixz="0" iyy="0.1" iyz="0" izz="0.1"/>
    </inertial>
    <visual>
      <origin rpy="0 0 0" xyz="0 0 0"/>
      <geometry>
        <mesh filename="package://sps/meshes/sensors/hokuyo.dae"/>
      </geometry>
    </visual>
    <collision>
      <origin rpy="0 0 0" xyz="0 0 0"/>
      <geometry>
        <mesh filename="package://sps/meshes/sensors/hokuyo_convex.dae"/>
      </geometry>
    </collision>
  </link>
  <gazebo reference="base_laser_front_link">
    <sensor name="base_laser_front" type="ray">
      <update_rate>10</update_rate>
      <pose>0 0 0 0 0 0</pose>
      <visualize>false</visualize>
      <ray>
        <scan>
          <horizontal>
            <samples>150</samples>
            <resolution>1.0</resolution>
            <min_angle>-1.57</min_angle>
            <max_angle>1.57</max_angle>
          </horizontal>
        </scan>
        <range>
          <min>0.05</min>
          <max>5.6</max>
          <resolution>0.36</resolution>
        </range>
      </ray>
      <plugin filename="libgazebo_ros_laser.so" name="gazebo_ros_base_laser_front_controller">
        <gaussianNoise>0.005</gaussianNoise>
        <updateRate>10</updateRate>
        <topicName>scan_front</topicName>
        <frameName>/base_laser_front_link</frameName>
      </plugin>
    </sensor>
  </gazebo>
  <!--
	<xacro:include filename="$(find sps)/urdf/kinova.xacro"/>
	-->
  <link name="base_link"/>
  <joint name="basejoining" type="fixed">
    <parent link="base_link"/>
    <child link="mobile_base_base_link"/>
    <origin rpy="0 0 0" xyz="0 0 0"/>
  </joint>
  <!--
	<joint name="joining" type="fixed">
			<parent link="mobile_base_chassis" />
			<child link="kinova_base_link"/>
			<origin rpy="-0.331613 -1.57 0" xyz="0.021 0.037667 0"/>
	</joint>
	-->
</robot>
