<?xml version="1.0" ?>
<!-- =================================================================================== -->
<!-- |    This document was autogenerated by xacro from mira.xacro                     | -->
<!-- |    EDITING THIS FILE BY HAND IS NOT RECOMMENDED                                 | -->
<!-- =================================================================================== -->
<robot name="mira">
  <link name="mobile_base_base_link"/>
  <joint name="mobile_base_base_link_to_base" type="fixed">
    <parent link="mobile_base_base_link"/>
    <child link="mobile_base_chassis"/>
    <origin rpy="1.5707963267948966 0 0" xyz="0 0 0"/>
  </joint>
  <link name="mobile_base_chassis">
    <visual>
      <origin rpy="0 -0 0" xyz="0 0 0"/>
      <geometry>
        <mesh filename="package://sps/urdf/mobile_base_models/chassis.stl"/>
      </geometry>
      <material name="chassis_material">
        <color rgba="0.74902 0.74902 0.74902 1.0"/>
      </material>
    </visual>
    <collision>
      <geometry>
        <mesh filename="package://sps/urdf/mobile_base_models/chassis.stl"/>
      </geometry>
    </collision>
    <inertial>
      <origin rpy="0 0 0" xyz="3.03885e-10 0.0866061 -4.21983e-12"/>
      <mass value="22"/>
      <inertia ixx="0.254" ixy="-1.648e-9" ixz="-2.434e-08" iyy="0.656" iyz="3.684e-10" izz="0.532"/>
    </inertial>
  </link>
  <gazebo reference="mobile_base_chassis">
    <material>Gazebo/DarkGrey</material>
  </gazebo>
  <joint name="mobile_base_joint_front_dx" type="continuous">
    <origin rpy="0 0 0" xyz="0.183 0.06 0.1355"/>
    <parent link="mobile_base_chassis"/>
    <child link="mobile_base_omniwheel_front_dx"/>
    <axis xyz="0 0 1"/>
    <limit effort="1" velocity="20"/>
    <joint_properties friction="0.0"/>
  </joint>
  <link name="mobile_base_omniwheel_front_dx">
    <visual>
      <origin rpy="3.141592653589793 0 0" xyz="0 0 0"/>
      <geometry>
        <mesh filename="package://sps/urdf/mobile_base_models/omniwheel_A.stl"/>
      </geometry>
    </visual>
    <collision>
      <origin rpy="3.141592653589793 0 0" xyz="0 0 0"/>
      <geometry>
        <cylinder length="0.08" radius="0.076"/>
      </geometry>
    </collision>
    <inertial>
      <origin rpy="0 1.5707963267948966 0" xyz="0 0 0"/>
      <mass value="3.5"/>
      <inertia ixx="0.006920666666666667" ixy="0" ixz="0" iyx="0" iyy="0.006920666666666667" iyz="0" izx="0" izy="0" izz="0.010108"/>
    </inertial>
  </link>
  <gazebo reference="mobile_base_omniwheel_front_dx">
    <material>Gazebo/Orange</material>
  </gazebo>
  <joint name="mobile_base_joint_front_sx" type="continuous">
    <origin rpy="0 0 0" xyz="0.183 0.06 -0.1355"/>
    <parent link="mobile_base_chassis"/>
    <child link="mobile_base_omniwheel_front_sx"/>
    <axis xyz="0 0 1"/>
    <limit effort="1" velocity="20"/>
    <joint_properties friction="0.0"/>
  </joint>
  <link name="mobile_base_omniwheel_front_sx">
    <visual>
      <origin rpy="3.141592653589793 0 0" xyz="0 0 0"/>
      <geometry>
        <mesh filename="package://sps/urdf/mobile_base_models/omniwheel_B.stl"/>
      </geometry>
    </visual>
    <collision>
      <origin rpy="3.141592653589793 0 0" xyz="0 0 0"/>
      <geometry>
        <cylinder length="0.08" radius="0.076"/>
      </geometry>
    </collision>
    <inertial>
      <origin rpy="0 1.5707963267948966 0" xyz="0 0 0"/>
      <mass value="3.5"/>
      <inertia ixx="0.006920666666666667" ixy="0" ixz="0" iyx="0" iyy="0.006920666666666667" iyz="0" izx="0" izy="0" izz="0.010108"/>
    </inertial>
  </link>
  <gazebo reference="mobile_base_omniwheel_front_sx">
    <material>Gazebo/Orange</material>
  </gazebo>
  <joint name="mobile_base_joint_rear_sx" type="continuous">
    <origin rpy="0 0 0" xyz="-0.183 0.06 -0.1355"/>
    <parent link="mobile_base_chassis"/>
    <child link="mobile_base_omniwheel_rear_sx"/>
    <axis xyz="0 0 1"/>
    <limit effort="1" velocity="20"/>
    <joint_properties friction="0.0"/>
  </joint>
  <link name="mobile_base_omniwheel_rear_sx">
    <visual>
      <origin rpy="3.141592653589793 0 0" xyz="0 0 0"/>
      <geometry>
        <mesh filename="package://sps/urdf/mobile_base_models/omniwheel_A.stl"/>
      </geometry>
    </visual>
    <collision>
      <origin rpy="3.141592653589793 0 0" xyz="0 0 0"/>
      <geometry>
        <cylinder length="0.08" radius="0.076"/>
      </geometry>
    </collision>
    <inertial>
      <origin rpy="0 1.5707963267948966 0" xyz="0 0 0"/>
      <mass value="3.5"/>
      <inertia ixx="0.006920666666666667" ixy="0" ixz="0" iyx="0" iyy="0.006920666666666667" iyz="0" izx="0" izy="0" izz="0.010108"/>
    </inertial>
  </link>
  <gazebo reference="mobile_base_omniwheel_rear_sx">
    <material>Gazebo/Orange</material>
  </gazebo>
  <joint name="mobile_base_joint_rear_dx" type="continuous">
    <origin rpy="0 0 0" xyz="-0.183 0.06 0.1355"/>
    <parent link="mobile_base_chassis"/>
    <child link="mobile_base_omniwheel_rear_dx"/>
    <axis xyz="0 0 1"/>
    <limit effort="1" velocity="20"/>
    <joint_properties friction="0.0"/>
  </joint>
  <link name="mobile_base_omniwheel_rear_dx">
    <visual>
      <origin rpy="3.141592653589793 0 0" xyz="0 0 0"/>
      <geometry>
        <mesh filename="package://sps/urdf/mobile_base_models/omniwheel_B.stl"/>
      </geometry>
    </visual>
    <collision>
      <origin rpy="3.141592653589793 0 0" xyz="0 0 0"/>
      <geometry>
        <cylinder length="0.08" radius="0.076"/>
      </geometry>
    </collision>
    <inertial>
      <origin rpy="0 1.5707963267948966 0" xyz="0 0 0"/>
      <mass value="3.5"/>
      <inertia ixx="0.006920666666666667" ixy="0" ixz="0" iyx="0" iyy="0.006920666666666667" iyz="0" izx="0" izy="0" izz="0.010108"/>
    </inertial>
  </link>
  <gazebo reference="mobile_base_omniwheel_rear_dx">
    <material>Gazebo/Orange</material>
  </gazebo>
  <joint name="mobile_base_camera_joint" type="fixed">
    <origin rpy="1.5707963267948966 0 1.5707963267948966" xyz="0.285 0 0.075"/>
    <parent link="mobile_base_base_link"/>
    <child link="mobile_base_camera_rgb_frame"/>
  </joint>
  <link name="mobile_base_camera_rgb_frame">
    <visual name="visual">
      <pose>0 0 0.27 0 0 0</pose>
      <geometry>
        <mesh filename="package://realsense2_description/meshes/d435.dae"/>
      </geometry>
    </visual>
    <collision>
      <origin rpy="0 0 0" xyz="0 0 0"/>
      <geometry>
        <cylinder length="0.062" radius="0.03"/>
      </geometry>
    </collision>
  </link>
  <gazebo reference="mobile_base_camera_rgb_frame">
    <material>Gazebo/Orange</material>
  </gazebo>
  <joint name="mobile_base_lidar_joint" type="fixed">
    <origin rpy="1.5707963267948966 0 1.5707963267948966" xyz="0.285 0 0.12"/>
    <parent link="mobile_base_base_link"/>
    <child link="mobile_base_lidar_frame"/>
  </joint>
  <link name="mobile_base_lidar_frame">
    <visual name="visual">
      <pose>0 0 0.27 0 0 0</pose>
      <geometry>
        <mesh filename="package://realsense_lidar/meshes/l515.dae"/>
      </geometry>
    </visual>
    <collision>
      <origin rpy="0 0 0" xyz="0 0 0"/>
      <geometry>
        <cylinder length="0.062" radius="0.03"/>
      </geometry>
    </collision>
  </link>
  <gazebo reference="mobile_base_lidar_frame">
    <material>Gazebo/Orange</material>
  </gazebo>
  <joint name="mobile_base_2d_lidar_joint" type="fixed">
    <origin rpy="1.5707963267948966 0 1.5707963267948966" xyz="0.18 0 0.17"/>
    <parent link="mobile_base_base_link"/>
    <child link="mobile_base_2d_lidar_frame"/>
  </joint>
  <link name="mobile_base_2d_lidar_frame">
    <visual name="visual">
      <pose>0 0 0.27 0 0 0</pose>
      <geometry>
        <mesh filename="package://turtlebot_explorer/meshes/rplidar.dae" scale="0.001 0.001 0.001"/>
      </geometry>
    </visual>
    <collision>
      <origin rpy="0 0 0" xyz="0 0 0"/>
      <geometry>
        <cylinder length="0.062" radius="0.03"/>
      </geometry>
    </collision>
  </link>
  <gazebo reference="mobile_base_2d_lidar_frame">
    <material>Gazebo/Orange</material>
  </gazebo>
  <gazebo>
    <plugin filename="libgazebo_ros_planar_move.so" name="robot_controller">
      <commandTopic>cmd_vel</commandTopic>
      <odometryTopic>odom</odometryTopic>
      <odometryFrame>odom</odometryFrame>
      <odometryRate>20.0</odometryRate>
      <robotBaseFrame>base_link</robotBaseFrame>
    </plugin>
  </gazebo>
  <gazebo reference="mobile_base_camera_rgb_frame">
    <sensor name="camera" type="camera">
      <update_rate>30.0</update_rate>
      <camera name="head">
        <horizontal_fov>1.97222</horizontal_fov>
        <image>
          <width>1920</width>
          <height>1080</height>
          <format>R8G8B8</format>
        </image>
        <clip>
          <near>0.02</near>
          <far>100</far>
        </clip>
        <noise>
          <type>gaussian</type>
          <mean>0.0</mean>
          <stddev>0.007</stddev>
        </noise>
      </camera>
      <plugin filename="libgazebo_ros_camera.so" name="camera_controller">
        <alwaysOn>true</alwaysOn>
        <updateRate>0.0</updateRate>
        <cameraName>mobile_base_camera</cameraName>
        <imageTopicName>mobile_base_image_raw</imageTopicName>
        <cameraInfoTopicName>mobile_base_camera_info</cameraInfoTopicName>
        <frameName>mobile_base_camera_rgb_optical_frame</frameName>
        <hackBaseline>0.07</hackBaseline>
        <distortionK1>-0.35925741</distortionK1>
        <distortionK2>0.16575977</distortionK2>
        <distortionK3>-0.03662964</distortionK3>
        <distortionT1>0.00264587</distortionT1>
        <distortionT2>0.00037099</distortionT2>
      </plugin>
    </sensor>
  </gazebo>
  <!-- Bumpers -->
  <gazebo reference="mobile_base_chassis">
    <sensor name="mobile_base_chassis_bumper" type="contact">
      <alwaysOn>true</alwaysOn>
      <updateRate>30.0</updateRate>
      <contact>
        <collision>base_link_fixed_joint_lump__mobile_base_chassis_collision</collision>
      </contact>
      <plugin filename="libgazebo_ros_bumper.so" name="gazebo_ros_bumper_controller">
        <bumperTopicName>bumper</bumperTopicName>
        <frameName>world</frameName>
        <updateRate>30.0</updateRate>
      </plugin>
    </sensor>
  </gazebo>
  <gazebo reference="mobile_base_omniwheel_front_dx">
    <sensor name="mobile_base_omniwheel_front_dx_collision_bumper" type="contact">
      <alwaysOn>true</alwaysOn>
      <updateRate>30.0</updateRate>
      <contact>
        <collision>mobile_base_omniwheel_front_dx_collision</collision>
      </contact>
      <plugin filename="libgazebo_ros_bumper.so" name="gazebo_ros_bumper_controller">
        <bumperTopicName>bumper</bumperTopicName>
        <frameName>world</frameName>
        <updateRate>30.0</updateRate>
      </plugin>
    </sensor>
  </gazebo>
  <gazebo reference="mobile_base_omniwheel_front_sx">
    <sensor name="mobile_base_omniwheel_front_sx_collision_bumper" type="contact">
      <alwaysOn>true</alwaysOn>
      <updateRate>30.0</updateRate>
      <contact>
        <collision>mobile_base_omniwheel_front_sx_collision</collision>
      </contact>
      <plugin filename="libgazebo_ros_bumper.so" name="gazebo_ros_bumper_controller">
        <bumperTopicName>bumper</bumperTopicName>
        <frameName>world</frameName>
        <updateRate>30.0</updateRate>
      </plugin>
    </sensor>
  </gazebo>
  <gazebo reference="mobile_base_omniwheel_rear_dx">
    <sensor name="mobile_base_omniwheel_rear_dx_collision_bumper" type="contact">
      <alwaysOn>true</alwaysOn>
      <updateRate>30.0</updateRate>
      <contact>
        <collision>mobile_base_omniwheel_rear_dx_collision</collision>
      </contact>
      <plugin filename="libgazebo_ros_bumper.so" name="gazebo_ros_bumper_controller">
        <bumperTopicName>bumper</bumperTopicName>
        <frameName>world</frameName>
        <updateRate>30.0</updateRate>
      </plugin>
    </sensor>
  </gazebo>
  <gazebo reference="mobile_base_omniwheel_rear_sx">
    <sensor name="mobile_base_omniwheel_rear_sx_collision_bumper" type="contact">
      <alwaysOn>true</alwaysOn>
      <updateRate>30.0</updateRate>
      <contact>
        <collision>mobile_base_omniwheel_rear_sx_collision</collision>
      </contact>
      <plugin filename="libgazebo_ros_bumper.so" name="gazebo_ros_bumper_controller">
        <bumperTopicName>bumper</bumperTopicName>
        <frameName>world</frameName>
        <updateRate>30.0</updateRate>
      </plugin>
    </sensor>
  </gazebo>
  <!-- The following is an handmade document. Please refer to the official repository at https://github.com/Kinovarobotics/kinova-ros/blob/master/kinova_description/urdf/j2s6s200_standalone.xacro -->
  <!-- Size of square 'camera' box -->
  <link name="kinova_base_link"/>
  <joint name="kinova_base_link_to_base" type="fixed">
    <parent link="kinova_base_link"/>
    <child link="kinova_link0"/>
    <origin rpy="0 0 0" xyz="0 0 0"/>
  </joint>
  <link name="kinova_link0">
    <visual>
      <origin rpy="0 0 0" xyz="0 0 0"/>
      <geometry>
        <mesh filename="package://sps/urdf/kinova_models/link0.stl"/>
      </geometry>
      <material name="link0_material">
        <color rgba="0.972549 0.529412 0.00392157 1"/>
      </material>
    </visual>
    <collision>
      <origin rpy="0 0 0" xyz="0 0 0"/>
      <geometry>
        <mesh filename="package://sps/urdf/kinova_models/link0.stl"/>
      </geometry>
      <material name="link0_material">
        <color rgba="0.972549 0.529412 0.00392157 1"/>
      </material>
    </collision>
    <inertial>
      <origin rpy="0 0 0" xyz="0 0 0.07825"/>
      <mass value="0.46784"/>
      <inertia ixx="0.0009512746666666666" ixy="0" ixz="0" iyx="0" iyy="0.0009512746666666666" iyz="0" izx="0" izy="0" izz="0.00037427200000000004"/>
    </inertial>
  </link>
  <gazebo reference="kinova_link0">
    <material>Gazebo/Indigo</material>
  </gazebo>
  <joint name="kinova_joint1" type="revolute">
    <origin rpy="0 0 0" xyz="0 0 0.1565"/>
    <parent link="kinova_link0"/>
    <child link="kinova_link1"/>
    <axis xyz="0 0 1"/>
    <limit effort="1" lower="-3.141592653589793" torque="40" upper="3.141592653589793" velocity="0.6283185307179586"/>
    <joint_properties friction="0"/>
  </joint>
  <link name="kinova_link1">
    <visual>
      <origin rpy="0 -1.5707963267948966 0" xyz="0 0 0"/>
      <geometry>
        <mesh filename="package://sps/urdf/kinova_models/link1.stl"/>
      </geometry>
      <material name="link1_material">
        <color rgba="0.615686 0.811765 0.929412 1"/>
      </material>
    </visual>
    <collision>
      <origin rpy="0 -1.5707963267948966 0" xyz="0 0 0"/>
      <geometry>
        <mesh filename="package://sps/urdf/kinova_models/link1.stl"/>
      </geometry>
      <material name="link1_material">
        <color rgba="0.615686 0.811765 0.929412 1"/>
      </material>
    </collision>
    <inertial>
      <origin xyz="0 0.0007 0.05925"/>
      <mass value="0.7477"/>
      <inertia ixx="0.0015203233333333334" ixy="0" ixz="0" iyx="0" iyy="0.0015203233333333334" iyz="0" izx="0" izy="0" izz="0.00059816"/>
    </inertial>
  </link>
  <gazebo reference="kinova_link1">
    <material>Gazebo/Indigo</material>
  </gazebo>
  <joint name="kinova_joint2" type="revolute">
    <origin rpy="0 -1.5707963267948966 0" xyz="0 0.0015 0.1185"/>
    <parent link="kinova_link1"/>
    <child link="kinova_link2"/>
    <axis xyz="0 0 1"/>
    <limit effort="1" lower="-3.141592653589793" torque="80" upper="3.141592653589793" velocity="0.6283185307179586"/>
    <joint_properties friction="0.0"/>
  </joint>
  <link name="kinova_link2">
    <visual>
      <origin rpy="-1.5707963267948966 -1.5707963267948966 1.5707963267948966" xyz="0 0 0"/>
      <geometry>
        <mesh filename="package://sps/urdf/kinova_models/link2.stl"/>
      </geometry>
      <material name="link2_material">
        <color rgba="0.498039 0.498039 0.498039 1.0"/>
      </material>
    </visual>
    <collision>
      <origin rpy="-1.5707963267948966 -1.5707963267948966 1.5707963267948966" xyz="0 0 0"/>
      <geometry>
        <mesh filename="package://sps/urdf/kinova_models/link2.stl"/>
      </geometry>
      <material name="link2_material">
        <color rgba="0.498039 0.498039 0.498039 1.0"/>
      </material>
    </collision>
    <inertial>
      <origin rpy="-1.5707963267948966 -1.5707963267948966 1.5707963267948966" xyz="0.205 0 0"/>
      <mass value="0.99"/>
      <inertia ixx="0.01050225" ixy="0" ixz="0" iyx="0" iyy="0.01050225" iyz="0" izx="0" izy="0" izz="0.0007920000000000001"/>
    </inertial>
  </link>
  <gazebo reference="kinova_link2">
    <material>Gazebo/Indigo</material>
  </gazebo>
  <joint name="kinova_joint3" type="revolute">
    <origin rpy="0 0 0" xyz="0.41 0 0"/>
    <parent link="kinova_link2"/>
    <child link="kinova_link3"/>
    <axis xyz="0 0 1"/>
    <limit effort="1" lower="-3.141592653589793" torque="40" upper="3.141592653589793" velocity="0.6283185307179586"/>
    <joint_properties friction="0.0"/>
  </joint>
  <link name="kinova_link3">
    <visual>
      <origin rpy="3.141592653589793 1.5707963267948966 0" xyz="0 0 0"/>
      <geometry>
        <mesh filename="package://sps/urdf/kinova_models/link3.stl"/>
      </geometry>
      <material name="link3_material">
        <color rgba="0.615686 0.811765 0.929412 1.0"/>
      </material>
    </visual>
    <collision>
      <origin rpy="3.141592653589793 1.5707963267948966 0" xyz="0 0 0"/>
      <geometry>
        <mesh filename="package://sps/urdf/kinova_models/link3.stl"/>
      </geometry>
      <material name="link3_material">
        <color rgba="0.615686 0.811765 0.929412 1.0"/>
      </material>
    </collision>
    <inertial>
      <origin rpy="3.141592653589793 1.5707963267948966 0" xyz="0.1035 0  -0.005625"/>
      <mass value="0.6763"/>
      <inertia ixx="0.0014202300000000002" ixy="0" ixz="0" iyx="0" iyy="0.0014202300000000002" iyz="0" izx="0" izy="0" izz="0.000304335"/>
    </inertial>
  </link>
  <gazebo reference="kinova_link3">
    <material>Gazebo/Indigo</material>
  </gazebo>
  <joint name="kinova_joint4" type="revolute">
    <origin rpy="0 1.5707963267948966 0" xyz="0.207 0  -0.01125"/>
    <parent link="kinova_link3"/>
    <child link="kinova_link4"/>
    <axis xyz="0 0 1"/>
    <limit effort="1" lower="-3.141592653589793" torque="20" upper="3.141592653589793" velocity="0.8377580409572781"/>
    <joint_properties friction="0.0"/>
  </joint>
  <link name="kinova_link4">
    <visual>
      <origin rpy="0 -1.5707963267948966 0" xyz="0 0 0"/>
      <geometry>
        <mesh filename="package://sps/urdf/kinova_models/link4.stl"/>
      </geometry>
      <material name="link4_material">
        <color rgba="0.615686 0.811765 0.929412 1.0"/>
      </material>
    </visual>
    <collision>
      <origin rpy="0 -1.5707963267948966 0" xyz="0 0 0"/>
      <geometry>
        <mesh filename="package://sps/urdf/kinova_models/link4.stl"/>
      </geometry>
      <material name="link4_material">
        <color rgba="0.615686 0.811765 0.929412 1.0"/>
      </material>
    </collision>
    <inertial>
      <origin rpy="0 0 0" xyz="-0.00125 0 0.04825"/>
      <mass value="0.463"/>
      <inertia ixx="0.00043213333333333345" ixy="0" ixz="0" iyx="0" iyy="0.00043213333333333345" iyz="0" izx="0" izy="0" izz="9.260000000000001e-05"/>
    </inertial>
  </link>
  <gazebo reference="kinova_link4">
    <material>Gazebo/Indigo</material>
  </gazebo>
  <joint name="kinova_joint5" type="continuous">
    <origin rpy="-1.5707963267948966 -1.5707963267948966 0" xyz="-0.0025 0 0.0965"/>
    <parent link="kinova_link4"/>
    <child link="kinova_link5"/>
    <axis xyz="0 0 1"/>
    <limit effort="1" lower="-3.141592653589793" torque="20" upper="3.141592653589793" velocity="0.8377580409572781"/>
    <joint_properties friction="0.0"/>
  </joint>
  <link name="kinova_link5">
    <visual>
      <origin rpy="-1.5707963267948966 0 3.141592653589793" xyz="0.0965 0 0"/>
      <geometry>
        <mesh filename="package://sps/urdf/kinova_models/link4.stl"/>
      </geometry>
      <material name="link4_material">
        <color rgba="0.615686 0.811765 0.929412 1.0"/>
      </material>
    </visual>
    <collision>
      <origin rpy="-1.5707963267948966 0 3.141592653589793" xyz="0.0965 0 0"/>
      <geometry>
        <mesh filename="package://sps/urdf/kinova_models/link4.stl"/>
      </geometry>
      <material name="link4_material">
        <color rgba="0.615686 0.811765 0.929412 1.0"/>
      </material>
    </collision>
    <inertial>
      <origin rpy="0 1.5707963267948966 0" xyz="0.05175 0 0.000125"/>
      <mass value="0.463"/>
      <inertia ixx="0.00043213333333333345" ixy="0" ixz="0" iyx="0" iyy="0.00043213333333333345" iyz="0" izx="0" izy="0" izz="9.260000000000001e-05"/>
    </inertial>
  </link>
  <gazebo reference="kinova_link5">
    <material>Gazebo/Indigo</material>
  </gazebo>
  <joint name="kinova_joint6" type="revolute">
    <origin rpy="1.5707963267948966 0 1.5707963267948966" xyz="0.101 0 0.00025"/>
    <parent link="kinova_link5"/>
    <child link="kinova_link6"/>
    <axis xyz="0 0 1"/>
    <limit effort="1" lower="-3.141592653589793" torque="20" upper="3.141592653589793" velocity="0.8377580409572781"/>
    <joint_properties friction="0.0"/>
  </joint>
  <link name="kinova_link6">
    <visual>
      <origin rpy="0 0 0" xyz="0 0 0"/>
      <geometry>
        <mesh filename="package://sps/urdf/kinova_models/link6.stl"/>
      </geometry>
      <material name="armsuppaxis001_(solid)_material">
        <color rgba="0.8 0.8 0.8 1.0"/>
      </material>
    </visual>
    <collision>
      <origin rpy="0 0 0" xyz="0 0 0"/>
      <geometry>
        <mesh filename="package://sps/urdf/kinova_models/link6.stl"/>
      </geometry>
      <material name="armsuppaxis001_(solid)_material">
        <color rgba="0.8 0.8 0.8 1.0"/>
      </material>
    </collision>
    <inertial>
      <origin rpy="0 0 0" xyz="0 0 0.032347"/>
      <mass value="0.059265"/>
      <inertia ixx="2.97358e-05" ixy="-5.33355e-13" ixz="-1.85073e-09" iyy="3.04484e-05" iyz="-4.08259e-11" izz="3.72715e-05"/>
    </inertial>
  </link>
  <gazebo reference="kinova_link6">
    <material>Gazebo/White</material>
  </gazebo>
  <gazebo reference="kinova_camera_rgb_frame">
    <material>Gazebo/Orange</material>
  </gazebo>
  <gazebo reference="kinova_link0">
    <selfCollide>true</selfCollide>
  </gazebo>
  <gazebo reference="kinova_link1">
    <selfCollide>true</selfCollide>
  </gazebo>
  <gazebo reference="kinova_link2">
    <selfCollide>true</selfCollide>
  </gazebo>
  <gazebo reference="kinova_link3">
    <selfCollide>true</selfCollide>
  </gazebo>
  <gazebo reference="kinova_link4">
    <selfCollide>true</selfCollide>
  </gazebo>
  <gazebo reference="kinova_link5">
    <selfCollide>true</selfCollide>
  </gazebo>
  <gazebo reference="kinova_link6">
    <selfCollide>true</selfCollide>
  </gazebo>
  <!-- Camera -->
  <gazebo reference="kinova_camera_rgb_frame">
    <sensor name="camera" type="camera">
      <update_rate>30.0</update_rate>
      <camera name="head">
        <horizontal_fov>1.97222</horizontal_fov>
        <image>
          <width>1920</width>
          <height>1080</height>
          <format>R8G8B8</format>
        </image>
        <clip>
          <near>0.02</near>
          <far>100</far>
        </clip>
        <noise>
          <type>gaussian</type>
          <mean>0.0</mean>
          <stddev>0.007</stddev>
        </noise>
      </camera>
      <plugin filename="libgazebo_ros_camera.so" name="camera_controller">
        <alwaysOn>true</alwaysOn>
        <updateRate>0.0</updateRate>
        <cameraName>kinova_camera</cameraName>
        <imageTopicName>kinova_image_raw</imageTopicName>
        <cameraInfoTopicName>kinova_camera_info</cameraInfoTopicName>
        <frameName>kinova_camera_rgb_optical_frame</frameName>
        <hackBaseline>0.07</hackBaseline>
        <distortionK1>-0.35925741</distortionK1>
        <distortionK2>0.16575977</distortionK2>
        <distortionK3>-0.03662964</distortionK3>
        <distortionT1>0.00264587</distortionT1>
        <distortionT2>0.00037099</distortionT2>
      </plugin>
    </sensor>
  </gazebo>
  <!-- Bumpers -->
  <gazebo reference="kinova_link0">
    <sensor name="kinova_link0_bumper" type="contact">
      <alwaysOn>true</alwaysOn>
      <updateRate>30.0</updateRate>
      <contact>
        <collision>base_link_fixed_joint_lump__kinova_link0_collision_1</collision>
      </contact>
      <plugin filename="libgazebo_ros_bumper.so" name="gazebo_ros_bumper_controller">
        <bumperTopicName>bumper</bumperTopicName>
        <frameName>world</frameName>
        <updateRate>30.0</updateRate>
      </plugin>
    </sensor>
  </gazebo>
  <gazebo reference="kinova_link1">
    <sensor name="kinova_link1_bumper" type="contact">
      <alwaysOn>true</alwaysOn>
      <updateRate>30.0</updateRate>
      <contact>
        <collision>kinova_link1_collision</collision>
      </contact>
      <plugin filename="libgazebo_ros_bumper.so" name="gazebo_ros_bumper_controller">
        <bumperTopicName>bumper</bumperTopicName>
        <frameName>world</frameName>
        <updateRate>30.0</updateRate>
      </plugin>
    </sensor>
  </gazebo>
  <gazebo reference="kinova_link2">
    <sensor name="kinova_link2_bumper" type="contact">
      <alwaysOn>true</alwaysOn>
      <updateRate>30.0</updateRate>
      <contact>
        <collision>kinova_link2_collision</collision>
      </contact>
      <plugin filename="libgazebo_ros_bumper.so" name="gazebo_ros_bumper_controller">
        <bumperTopicName>bumper</bumperTopicName>
        <frameName>world</frameName>
        <updateRate>30.0</updateRate>
      </plugin>
    </sensor>
  </gazebo>
  <gazebo reference="kinova_link3">
    <sensor name="kinova_link3_bumper" type="contact">
      <alwaysOn>true</alwaysOn>
      <updateRate>30.0</updateRate>
      <contact>
        <collision>kinova_link3_collision</collision>
      </contact>
      <plugin filename="libgazebo_ros_bumper.so" name="gazebo_ros_bumper_controller">
        <bumperTopicName>bumper</bumperTopicName>
        <frameName>world</frameName>
        <updateRate>30.0</updateRate>
      </plugin>
    </sensor>
  </gazebo>
  <gazebo reference="kinova_link4">
    <sensor name="kinova_link4_bumper" type="contact">
      <alwaysOn>true</alwaysOn>
      <updateRate>30.0</updateRate>
      <contact>
        <collision>kinova_link4_collision</collision>
      </contact>
      <plugin filename="libgazebo_ros_bumper.so" name="gazebo_ros_bumper_controller">
        <bumperTopicName>bumper</bumperTopicName>
        <frameName>world</frameName>
        <updateRate>30.0</updateRate>
      </plugin>
    </sensor>
  </gazebo>
  <gazebo reference="kinova_link5">
    <sensor name="kinova_link5_bumper" type="contact">
      <alwaysOn>true</alwaysOn>
      <updateRate>30.0</updateRate>
      <contact>
        <collision>kinova_link5_collision</collision>
      </contact>
      <plugin filename="libgazebo_ros_bumper.so" name="gazebo_ros_bumper_controller">
        <bumperTopicName>bumper</bumperTopicName>
        <frameName>world</frameName>
        <updateRate>30.0</updateRate>
      </plugin>
    </sensor>
  </gazebo>
  <gazebo reference="kinova_link6">
    <sensor name="kinova_link6_bumper" type="contact">
      <alwaysOn>true</alwaysOn>
      <updateRate>30.0</updateRate>
      <contact>
        <collision>kinova_link6_collision</collision>
      </contact>
      <plugin filename="libgazebo_ros_bumper.so" name="gazebo_ros_bumper_controller">
        <bumperTopicName>bumper</bumperTopicName>
        <frameName>world</frameName>
        <updateRate>30.0</updateRate>
      </plugin>
    </sensor>
  </gazebo>
  <!-- Controller -->
  <gazebo>
    <plugin filename="libgazebo_ros_control.so" name="gazebo_ros_control">
		</plugin>
  </gazebo>
  <transmission name="kinova_joint1_trans">
    <type>transmission_interface/SimpleTransmission</type>
    <joint name="kinova_joint1">
      <hardwareInterface>hardware_interface/PositionJointInterface</hardwareInterface>
    </joint>
    <actuator name="kinova_joint1_motor">
      <hardwareInterface>hardware_interface/PositionJointInterface</hardwareInterface>
      <mechanicalReduction>1</mechanicalReduction>
    </actuator>
  </transmission>
  <transmission name="kinova_joint2_trans">
    <type>transmission_interface/SimpleTransmission</type>
    <joint name="kinova_joint2">
      <hardwareInterface>hardware_interface/PositionJointInterface</hardwareInterface>
    </joint>
    <actuator name="kinova_joint2_motor">
      <hardwareInterface>hardware_interface/PositionJointInterface</hardwareInterface>
      <mechanicalReduction>1</mechanicalReduction>
    </actuator>
  </transmission>
  <transmission name="kinova_joint3_trans">
    <type>transmission_interface/SimpleTransmission</type>
    <joint name="kinova_joint3">
      <hardwareInterface>hardware_interface/PositionJointInterface</hardwareInterface>
    </joint>
    <actuator name="kinova_joint3_motor">
      <hardwareInterface>hardware_interface/PositionJointInterface</hardwareInterface>
      <mechanicalReduction>1</mechanicalReduction>
    </actuator>
  </transmission>
  <transmission name="kinova_joint4_trans">
    <type>transmission_interface/SimpleTransmission</type>
    <joint name="kinova_joint4">
      <hardwareInterface>hardware_interface/PositionJointInterface</hardwareInterface>
    </joint>
    <actuator name="kinova_joint4_motor">
      <hardwareInterface>hardware_interface/PositionJointInterface</hardwareInterface>
      <mechanicalReduction>1</mechanicalReduction>
    </actuator>
  </transmission>
  <transmission name="kinova_joint5_trans">
    <type>transmission_interface/SimpleTransmission</type>
    <joint name="kinova_joint5">
      <hardwareInterface>hardware_interface/PositionJointInterface</hardwareInterface>
    </joint>
    <actuator name="kinova_joint5_motor">
      <hardwareInterface>hardware_interface/PositionJointInterface</hardwareInterface>
      <mechanicalReduction>1</mechanicalReduction>
    </actuator>
  </transmission>
  <transmission name="kinova_joint6_trans">
    <type>transmission_interface/SimpleTransmission</type>
    <joint name="kinova_joint6">
      <hardwareInterface>hardware_interface/PositionJointInterface</hardwareInterface>
    </joint>
    <actuator name="kinova_joint6_motor">
      <hardwareInterface>hardware_interface/PositionJointInterface</hardwareInterface>
      <mechanicalReduction>1</mechanicalReduction>
    </actuator>
  </transmission>
  <link name="base_link"/>
  <joint name="basejoining" type="fixed">
    <parent link="base_link"/>
    <child link="mobile_base_base_link"/>
    <origin rpy="0 0 0" xyz="0 0 0"/>
  </joint>
  <joint name="joining" type="fixed">
    <parent link="mobile_base_chassis"/>
    <child link="kinova_base_link"/>
    <origin rpy="-0.331613 -1.57 0" xyz="0.021 0.037667 0"/>
  </joint>
</robot>
